Workbook

Sheet 3rd A 
A1: AMC ENGINEERING COLLEGE
A2: DEPARTMENT OF COMPUTER SCIENCE AND ENGINEERING
A3: 3rd A NAME LIST
A4: STAFF INCHARGE: Ms Shwetha K R
A5: Digital Design and Computer Organization
A6: SL NO. | B6: USN | C6: NAME OF THE STUDENT | D6: CO1 | E6: CO1 | F6: CO1 | G6: CO1 | H6: CO2 | I6: CO2 | J6: CO2 | K6: CO2 | L6: TOTAL | M6: CO3 | N6: CO4 | O6: CO3 | P6: CO4 | Q6: CO5 | R6: CO4 | S6: CO5 | T6: CO4 | U6: TOTAL
D7: 1a[8] | E7: 1b[12] | F7: 2a[8]] | G7: 2b[12] | H7: 3a[12] | I7: 3b[8] | J7: 4a[12] | K7: 4b[8] | M7: 1a[8] | N7: 1b[12] | O7: 2a[8]] | P7: 2b[12] | Q7: 3a[8] | R7: 3b[12] | S7: 4a[8] | T7: 4b[12]
A8: 1 | B8: 1AM22CS001 | C8: AADARSH | D8: 6 | E8: 4 | J8: 2 | K8: 0 | L8: 12 | M8: 6 | N8: 6 | S8: 6 | T8: 0 | U8: 18
A9: 2 | B9: 1AM22CS002 | C9: ABHIJEET SHINDE | D9: 8 | E9: 4 | J9: 10 | K9: 4 | L9: 31 | M9: 2 | N9: 0 | S9: 6 | T9: 8 | U9: 16
A10: 3 | B10: 1AM22CS003 | C10: ABHILASHA KUMARI | D10: 8 | E10: 9 | J10: 10 | K10: 0 | L10: 27 | M10: 8 | N10: 0 | Q10: 8 | R10: 0 | S10: 6 | T10: 0 | U10: 16
A11: 4 | B11: 1AM22CS004 | C11: ABHISHEK B | D11: 8 | E11: 7 | J11: 8 | K11: 0 | L11: 22 | M11: 8 | N11: 3 | Q11: 0 | R11: 7 | U11: 18
A12: 5 | B12: 1AM22CS005 | C12: ABHISHEK K | D12: 8 | E12: 7 | J12: 4 | K12: 0 | L12: 19 | M12: 1 | N12: 6 | Q12: 0 | R12: 0 | U12: 7
A13: 6 | B13: 1AM22CS006 | C13: ABU SUFIYAN | D13: 0 | E13: 0 | J13: 0 | K13: 0 | L13: AB | M13: 8 | N13: 0 | Q13: 7 | R13: 10 | U13: 25
A14: 7 | B14: 1AM22CS007 | C14: ACHYUTH KUMAR G V | D14: 8 | E14: 12 | J14: 9 | K14: 4 | L14: 33 | M14: 8 | N14: 4 | S14: 8 | T14: 12 | U14: 32
A15: 8 | B15: 1AM22CS008 | C15: ADITYA KUMAR SINGH | D15: 7 | E15: 11 | J15: 6 | K15: 6 | L15: 30 | M15: 6 | N15: 0 | Q15: 0 | R15: 0 | U15: 6
A16: 9 | B16: 1AM22CS011 | C16: AISHWARYA RAMACHANDRA BAKALE | D16: 7 | E16: 2 | J16: 9 | K16: 6 | L16: 34 | M16: 7 | N16: 3 | S16: 6 | T16: 0 | U16: 16
A17: 10 | B17: 1AM22CS012 | C17: AJITH V | D17: 8 | E17: 8 | J17: 8 | K17: 1 | L17: 25 | M17: 8 | N17: 10 | S17: 6 | T17: 6 | U17: 30
A18: 11 | B18: 1AM22CS013 | C18: AKARSH CHOUDHARY | D18: 7 | E18: 6 | J18: 9 | K18: 2 | L18: 24 | M18: 2 | N18: 0 | O18: 0 | P18: 2 | S18: 3 | T18: 3 | U18: 5
A19: 12 | B19: 1AM22CS014 | C19: AKHILESH A M | D19: 8 | E19: 12 | J19: 12 | K19: 3 | L19: 35 | M19: 5 | N19: 3 | Q19: 8 | R19: 0 | U19: 16
A20: 13 | B20: 1AM22CS017 | C20: AMAN KUMAR | D20: 8 | E20: 12 | J20: 12 | K20: 3 | L20: 20 | M20: 5 | N20: 3 | Q20: 8 | R20: 0 | U20: 6
A21: 14 | B21: 1AM22CS018 | C21: AMBUJA T | D21: 7 | E21: 12 | J21: 9 | K21: 0 | L21: 28 | M21: 6 | N21: 8 | Q21: 6 | R21: 4 | U21: 24
A22: 15 | B22: 1AM22CS019 | C22: AMEEN AHMED | D22: 8 | E22: 11 | J22: 4 | K22: 5 | L22: 28 | M22: 7 | N22: 0 | Q22: 6 | R22: 6 | U22: 19
A23: 16 | B23: 1AM22CS021 | C23: AMRESH KUSHWAHA | D23: 8 | E23: 9 | J23: 8 | K23: 1 | L23: 26 | M23: 6 | N23: 8 | Q23: 8 | R23: 5 | U23: 27
A24: 17 | B24: 1AM22CS022 | C24: ANANGA REKHA B | D24: 8 | E24: 12 | J24: 12 | K24: 8 | L24: 40 | M24: 0 | N24: 0 | O24: 8 | P24: 12 | Q24: 8 | R24: 12 | S24: 0 | T24: 0 | U24: 40
A25: 18 | B25: 1AM22CS023 | C25: ANIRUDH ADITYA E | D25: 8 | E25: 4 | F25: 1 | J25: 7 | K25: 2 | L25: 21 | M25: 7 | N25: 0 | O25: 6 | P25: 0 | Q25: 4 | R25: 4 | S25: 4 | T25: 0 | U25: 15
A26: 19 | B26: 1AM22CS024 | C26: ANTONY ALAN | D26: 8 | E26: 10 | J26: 8 | K26: 6 | L26: 35 | M26: 8 | N26: 12 | O26: 0 | P26: 0 | Q26: 8 | R26: 12 | S26: 0 | T26: 0 | U26: 40
A27: 20 | B27: 1AM22CS025 | C27: ARCHIT MAHAJAN | D27: 8 | E27: 8 | J27: 7 | K27: 1 | L27: 24 | M27: 8 | N27: 7 | Q27: 6 | R27: 6 | U27: 27
A28: 21 | B28: 1AM22CS026 | C28: ARK THRINATH | D28: 8 | E28: 8 | J28: 9 | K28: 0 | L28: 25 | M28: 5 | N28: 2 | S28: 1 | T28: 0 | U28: 16
A29: 22 | B29: 1AM22CS027 | C29: ARPITHA H M | D29: 8 | E29: 12 | J29: 10 | K29: 7 | L29: 37 | M29: 8 | N29: 9 | Q29: 8 | R29: 11 | U29: 36
A30: 23 | B30: 1AM22CS028 | C30: ARUN KUMAR P | F30: 8 | G30: 8 | H30: 0 | I30: 5 | J30: 8 | K30: 0 | L30: 24 | M30: 8 | N30: 12 | S30: 6 | T30: 12 | U30: 38
A31: 24 | B31: 1AM22CS029 | C31: ARYAN ANIL | D31: 8 | E31: 12 | J31: 10 | K31: 3 | L31: 33 | M31: 8 | N31: 10 | S31: 7 | T31: 0 | U31: 25
A32: 25 | B32: 1AM22CS030 | C32: AVINASH DUBEY | D32: 8 | E32: 11 | J32: 9 | K32: 0 | L32: 28 | M32: 7 | N32: 0 | Q32: 8 | R32: 2 | U32: 17
A33: 26 | B33: 1AM22CS031 | C33: AWANTIKA | D33: 8 | E33: 12 | J33: 5 | K33: 0 | L33: 25 | M33: 8 | N33: 10 | S33: 6 | T33: 0 | U33: 26
A34: 27 | B34: 1AM22CS032 | C34: AYUSHI KUMARI | D34: 8 | E34: 12 | J34: 2 | K34: 0 | L34: 22 | M34: 2 | N34: 0 | Q34: 4 | R34: 0 | U34: 6
A35: 28 | B35: 1AM22CS033 | C35: BALAKRISHNA V | D35: 7 | E35: 2 | J35: 1 | K35: 0 | L35: 11 | M35: 5 | N35: 0 | Q35: 7 | R35: 10 | S35: 1 | T35: 0 | U35: 22
A36: 29 | B36: 1AM22CS034 | C36: BASAVARAJ | D36: 5 | E36: 8 | J36: 4 | K36: 2 | L36: 19 | M36: 8 | N36: 0 | S36: 6 | T36: 0 | U36: 14
A37: 30 | B37: 1AM22CS035 | C37: BHAVAN PANDE | F37: 8 | G37: 12 | J37: 12 | K37: 8 | L37: 40 | M37: 8 | N37: 11 | Q37: 8 | R37: 12 | U37: 39
A38: 31 | B38: 1AM22CS036 | C38: BURLA RAJAMOULI | F38: 5 | G38: 0 | H38: 3 | I38: 0 | J38: 8 | K38: 2 | L38: 9 | O38: 3 | P38: 0 | U38: 14
A39: 32 | B39: 1AM22CS037 | C39: C B GAURAV GANAPATHY | D39: 8 | E39: 12 | H39: 0 | I39: 0 | L39: 20 | M39: 4 | N39: 0 | Q39: 5 | R39: 8 | U39: 17
A40: 33 | B40: 1AM22CS038 | C40: C V SAI SARANYA | D40: 8 | E40: 12 | J40: 12 | K40: 6 | L40: 38 | M40: 7 | N40: 8 | Q40: 8 | R40: 12 | U40: 35
...

Sheet 3rdA_internal
A6: SL NO. | B6: USN | C6: NAME OF THE STUDENT | D6: IA1 | E6: IA2 | F6: AVERAGE | G6: REDUCED TO 25 | H6: LAB MARKS | I6: ASSIGNMENT | J6: INTERNAL_TOTAL
A8: 1 | B8: 1AM22CS001 | C8: AADARSH | D8: {='3rd A '!L8:L65} -> 12 | E8: {='3rd A '!U8:U65} -> 18 | F8: =AVERAGE(D8,E8) -> 15 | G8: =(F8/40)*25 -> 9.375 | J8: =G8+H8+I8 -> 9.375
A9: 2 | B9: 1AM22CS002 | C9: ABHIJEET SHINDE | D9: 31 | E9: 16 | F9: =AVERAGE(D9,E9) -> 23.5 | G9: =(F9/40)*25 -> 14.6875 | J9: =G9+H9+I9 -> 14.6875
A10: 3 | B10: 1AM22CS003 | C10: ABHILASHA KUMARI | D10: 27 | E10: 16 | F10: =AVERAGE(D10,E10) -> 21.5 | G10: =(F10/40)*25 -> 13.4375 | J10: =G10+H10+I10 -> 13.4375
A11: 4 | B11: 1AM22CS004 | C11: ABHISHEK B | D11: 22 | E11: 18 | F11: =AVERAGE(D11,E11) -> 20 | G11: =(F11/40)*25 -> 12.5 | J11: =G11+H11+I11 -> 12.5
A12: 5 | B12: 1AM22CS005 | C12: ABHISHEK K | D12: 19 | E12: 7 | F12: =AVERAGE(D12,E12) -> 13 | G12: =(F12/40)*25 -> 8.125 | J12: =G12+H12+I12 -> 8.125
A13: 6 | B13: 1AM22CS006 | C13: ABU SUFIYAN | D13: AB | E13: 25 | F13: =AVERAGE(D13,E13) -> 25 | G13: =(F13/40)*25 -> 15.625 | J13: =G13+H13+I13 -> 15.625
A14: 7 | B14: 1AM22CS007 | C14: ACHYUTH KUMAR G V | D14: 33 | E14: 32 | F14: =AVERAGE(D14,E14) -> 32.5 | G14: =(F14/40)*25 -> 20.3125 | J14: =G14+H14+I14 -> 20.3125
A15: 8 | B15: 1AM22CS008 | C15: ADITYA KUMAR SINGH | D15: 30 | E15: 6 | F15: =AVERAGE(D15,E15) -> 18 | G15: =(F15/40)*25 -> 11.25 | J15: =G15+H15+I15 -> 11.25
A16: 9 | B16: 1AM22CS011 | C16: AISHWARYA RAMACHANDRA BAKALE | D16: 34 | E16: 16 | F16: =AVERAGE(D16,E16) -> 25 | G16: =(F16/40)*25 -> 15.625 | J16: =G16+H16+I16 -> 15.625
A17: 10 | B17: 1AM22CS012 | C17: AJITH V | D17: 25 | E17: 30 | F17: =AVERAGE(D17,E17) -> 27.5 | G17: =(F17/40)*25 -> 17.1875 | J17: =G17+H17+I17 -> 17.1875
A18: 11 | B18: 1AM22CS013 | C18: AKARSH CHOUDHARY | D18: 24 | E18: 5 | F18: =AVERAGE(D18,E18) -> 14.5 | G18: =(F18/40)*25 -> 9.0625 | J18: =G18+H18+I18 -> 9.0625
A19: 12 | B19: 1AM22CS014 | C19: AKHILESH A M | D19: 35 | E19: 16 | F19: =AVERAGE(D19,E19) -> 25.5 | G19: =(F19/40)*25 -> 15.9375 | J19: =G19+H19+I19 -> 15.9375
A20: 13 | B20: 1AM22CS017 | C20: AMAN KUMAR | D20: 20 | E20: 6 | F20: =AVERAGE(D20,E20) -> 13 | G20: =(F20/40)*25 -> 8.125 | J20: =G20+H20+I20 -> 8.125
A21: 14 | B21: 1AM22CS018 | C21: AMBUJA T | D21: 28 | E21: 24 | F21: =AVERAGE(D21,E21) -> 26 | G21: =(F21/40)*25 -> 16.25 | J21: =G21+H21+I21 -> 16.25
A22: 15 | B22: 1AM22CS019 | C22: AMEEN AHMED | D22: 28 | E22: 19 | F22: =AVERAGE(D22,E22) -> 23.5 | G22: =(F22/40)*25 -> 14.6875 | J22: =G22+H22+I22 -> 14.6875
A23: 16 | B23: 1AM22CS021 | C23: AMRESH KUSHWAHA | D23: 26 | E23: 27 | F23: =AVERAGE(D23,E23) -> 26.5 | G23: =(F23/40)*25 -> 16.5625 | J23: =G23+H23+I23 -> 16.5625
A24: 17 | B24: 1AM22CS022 | C24: ANANGA REKHA B | D24: 40 | E24: 40 | F24: =AVERAGE(D24,E24) -> 40 | G24: =(F24/40)*25 -> 25 | J24: =G24+H24+I24 -> 25
A25: 18 | B25: 1AM22CS023 | C25: ANIRUDH ADITYA E | D25: 21 | E25: 15 | F25: =AVERAGE(D25,E25) -> 18 | G25: =(F25/40)*25 -> 11.25 | J25: =G25+H25+I25 -> 11.25
... A64: 57 | B64: LATERAL ENTRY | C64: VISHNU PRASAD | D64: 27 | E64: 21 | F64: =AVERAGE(D64,E64) -> 24 | G64: =(F64/40)*25 -> 15 | J64: =G64+H64+I64 -> 15
A65: 58 | C65: ARUN | D65: 14 | E65: 13 | F65: =AVERAGE(D65,E65) -> 13.5 | G65: =(F65/40)*25 -> 8.4375 | J65: =G65+H65+I65 -> 8.4375

Sheet 3rdA_total
A6: SL NO. | B6: USN | C6: NAME OF THE STUDENT | D6: INTERNAL | E6: EXTERNAL | F6: TOTAL
A8: 1 | B8: 1AM22CS001 | C8: AADARSH | D8: {='3rdA_internal'!J8:J65} -> 9.375 | F8: =D8+E8 -> 9.375
A9: 2 | B9: 1AM22CS002 | C9: ABHIJEET SHINDE | D9: 14.6875 | F9: =D9+E9 -> 14.6875
A10: 3 | B10: 1AM22CS003 | C10: ABHILASHA KUMARI | D10: 13.4375 | F10: =D10+E10 -> 13.4375
A11: 4 | B11: 1AM22CS004 | C11: ABHISHEK B | D11: 12.5 | F11: =D11+E11 -> 12.5
A12: 5 | B12: 1AM22CS005 | C12: ABHISHEK K | D12: 8.125 | F12: =D12+E12 -> 8.125
A13: 6 | B13: 1AM22CS006 | C13: ABU SUFIYAN | D13: 15.625 | F13: =D13+E13 -> 15.625
A14: 7 | B14: 1AM22CS007 | C14: ACHYUTH KUMAR G V | D14: 20.3125 | F14: =D14+E14 -> 20.3125
A15: 8 | B15: 1AM22CS008 | C15: ADITYA KUMAR SINGH | D15: 11.25 | F15: =D15+E15 -> 11.25
A16: 9 | B16: 1AM22CS011 | C16: AISHWARYA RAMACHANDRA BAKALE | D16: 15.625 | F16: =D16+E16 -> 15.625
A17: 10 | B17: 1AM22CS012 | C17: AJITH V | D17: 17.1875 | F17: =D17+E17 -> 17.1875
A18: 11 | B18: 1AM22CS013 | C18: AKARSH CHOUDHARY | D18: 9.0625 | F18: =D18+E18 -> 9.0625
A19: 12 | B19: 1AM22CS014 | C19: AKHILESH A M | D19: 15.9375 | F19: =D19+E19 -> 15.9375
A20: 13 | B20: 1AM22CS017 | C20: AMAN KUMAR | D20: 8.125 | F20: =D20+E20 -> 8.125
... A64: 57 | B64: LATERAL ENTRY | C64: VISHNU PRASAD | D64: 15 | F64: =D64+E64 -> 15
A65: 58 | C65: ARUN | D65: 8.4375 | F65: =D65+E65 -> 8.4375

Sheet 3rd B 
A1: AMC ENGINEERING COLLEGE
A2: DEPARTMENT OF COMPUTER SCIENCE AND ENGINEERING
A3: 3rd B NAME LIST
A4: STAFF INCHARGE: Ms Shwetha K R
A5: Digital Design and Computer Organization
A6: SL NO. | B6: USN | C6: NAME OF THE STUDENT | D6: CO1 | E6: CO1 | F6: CO1 | G6: CO1 | H6: CO2 | I6: CO2 | J6: CO2 | K6: CO2 | L6: TOTAL | M6: CO3 | N6: CO4 | O6: CO3 | P6: CO4 | Q6: CO5 | R6: CO4 | S6: CO5 | T6: CO4 | U6: TOTAL
D7: 1a[8] | E7: 1b[12] | F7: 2a[8]] | G7: 2b[12] | H7: 3a[12] | I7: 3b[8] | J7: 4a[12] | K7: 4b[8] | M7: 1a[8] | N7: 1b[12] | O7: 2a[8]] | P7: 2b[12] | Q7: 3a[8] | R7: 3b[12] | S7: 4a[8] | T7: 4b[12]
A8: 1 | B8: 1AM22CS059 | C8: GAGANA R M | D8: 8 | E8: 10 | J8: 11 | K8: 8 | L8: 37 | M8: 8 | N8: 12 | Q8: 8 | R8: 12 | U8: 40
A9: 2 | B9: 1AM22CS060 | C9: GANASHREE A | D9: 7 | E9: 11 | L9: 18 | M9: 8 | N9: 2 | S9: 6 | T9: 1 | U9: 17
A10: 3 | B10: 1AM22CS061 | C10: GANESH B R | D10: 7 | E10: 0 | L10: 7 | M10: 7 | N10: 0 | Q10: 7 | R10: 0 | U10: 14
A11: 4 | B11: 1AM22CS062 | C11: GAYITHRI R | D11: 8 | E11: 11 | J11: 8 | K11: 0 | L11: 27 | M11: 2 | N11: 0 | O11: 3 | P11: 0 | Q11: 8 | R11: 12 | U11: 23
A12: 5 | B12: 1AM22CS063 | C12: GOLDI KUMARI | D12: 8 | E12: 10 | J12: 8 | K12: 1 | L12: 27 | M12: 8 | N12: 10 | S12: 6 | T12: 8 | U12: 32
A13: 6 | B13: 1AM22CS064 | C13: GOPIKA M U | D13: 8 | E13: 12 | J13: 12 | K13: 0 | L13: 32 | M13: 8 | N13: 1 | S13: 8 | T13: 12 | U13: 29
A14: 7 | B14: 1AM22CS065 | C14: GOPIMOHAN MUKHERJEE | D14: 8 | E14: 10 | J14: 9 | K14: 3 | L14: 30 | M14: 8 | N14: 12 | Q14: 8 | R14: 0 | S14: 0 | T14: 10 | U14: 30
A15: 8 | B15: 1AM22CS066 | C15: GOWDA NAVEENKUMAR UCHE | D15: 8 | E15: 10 | J15: 8 | K15: 0 | L15: 26 | M15: 7 | N15: 11 | S15: 0 | T15: 0 | U15: 18
A16: 9 | B16: 1AM22CS067 | C16: GURUPRADAD | D16: 8 | E16: 12 | J16: 8 | K16: 0 | L16: 28 | M16: 5 | N16: 0 | S16: 8 | T16: 0 | U16: 13
A17: 10 | B17: 1AM22CS068 | C17: HARASH SANGRAL | D17: 8 | E17: 12 | J17: 12 | K17: 8 | L17: 40 | M17: 8 | N17: 12 | Q17: 8 | R17: 5 | U17: 33
A18: 11 | B18: 1AM22CS069 | C18: HARI KRISHNA YADAV C | D18: 8 | E18: 9 | J18: 10 | K18: 6 | L18: 33 | M18: 8 | N18: 11 | Q18: 8 | R18: 12 | U18: 39
A19: 12 | B19: 1AM22CS070 | C19: HARSHITH G M | D19: 8 | E19: 11 | J19: 8 | K19: 3 | L19: 30 | M19: 6 | N19: 10 | U19: 16
A20: 13 | B20: 1AM22CS071 | C20: HARSHITHA R | D20: 8 | E20: 12 | J20: 10 | K20: 8 | L20: 38 | M20: 8 | N20: 11 | Q20: 8 | R20: 12 | U20: 39
A21: 14 | B21: 1AM22CS072 | C21: HARSHITHA V R | D21: 8 | E21: 12 | J21: 11 | K21: 8 | L21: 39 | M21: 8 | N21: 12 | Q21: 8 | R21: 12 | U21: 40
A22: 15 | B22: 1AM22CS073 | C22: HEMANTH KUMAR K | D22: 8 | E22: 10 | J22: 4 | K22: 3 | L22: 25 | M22: 3 | N22: 0 | S22: 0 | T22: 1 | U22: 4
A23: 16 | B23: 1AM22CS074 | C23: HEMANTHA M | D23: 7 | E23: 7 | J23: 9 | K23: 0 | L23: 23 | M23: 2 | N23: 1 | S23: 5 | T23: 0 | U23: 8
A24: 17 | B24: 1AM22CS075 | C24: HEMASHREE R | D24: 8 | E24: 11 | J24: 12 | K24: 7 | L24: 38 | M24: 8 | N24: 8 | Q24: 5 | R24: 12 | U24: 34
A25: 18 | B25: 1AM22CS077 | C25: HIMANSHU SAHU | D25: 8 | E25: 11 | J25: 12 | K25: 6 | L25: 37 | M25: 8 | N25: 12 | Q25: 6 | R25: 12 | U25: 38
A26: 19 | B26: 1AM22CS078 | C26: HITHYSHI T S | D26: 8 | E26: 12 | J26: 12 | K26: 6 | L26: 38 | M26: 7 | N26: 12 | Q26: 8 | R26: 12 | U26: 39
A27: 20 | B27: 1AM22CS079 | C27: HUDA FATHIMA A | D27: 8 | E27: 6 | H27: 11 | I27: 0 | L27: 25 | O27: 8 | P27: 11 | Q27: 8 | R27: 12 | U27: 39
A28: 21 | B28: 1AM22CS080 | C28: IFFATH FATHIMA | D28: 8 | E28: 10 | J28: 9 | K28: 6 | L28: 33 | M28: 8 | N28: 12 | Q28: 8 | R28: 12 | U28: 40
A29: 22 | B29: 1AM22CS081 | C29: IQRA TAHREEM | D29: 8 | E29: 10 | J29: 10 | K29: 6 | L29: 34 | M29: 6 | N29: 9 | S29: 7 | T29: 0 | U29: 22
A30: 23 | B30: 1AM22CS082 | C30: J M MUSHARAF | D30: 8 | E30: 12 | H30: 10 | I30: 8 | J30: 11 | K30: 8 | L30: 39 | M30: 8 | N30: 12 | Q30: 8 | R30: 12 | U30: 40
A31: 24 | B31: 1AM22CS083 | C31: JANANI V | D31: 7 | E31: 8 | J31: 10 | K31: 6 | L31: 31 | M31: 8 | N31: 0 | S31: 8 | T31: 12 | U31: 28
A32: 25 | B32: 1AM22CS084 | C32: JAWAD KHAN | D32: 7 | E32: 5 | L32: 12 | M32: 2 | N32: 1 | Q32: 2 | R32: 2 | U32: 7
A33: 26 | B33: 1AM22CS085 | C33: JAYARANI BASANAGOUDA TAMMANNAVAR | D33: 8 | E33: 12 | J33: 10 | K33: 6 | L33: 36 | M33: 7 | N33: 11 | Q33: 8 | R33: 12 | U33: 38
A34: 27 | B34: 1AM22CS086 | C34: JEEVAN GOWDA B D | D34: 8 | E34: 6 | J34: 7 | K34: 0 | L34: 21 | M34: 0 | N34: 2 | Q34: 8 | R34: 0 | T34: 10
A35: 28 | B35: 1AM22CS087 | C35: JITHUSHREE S L | D35: 8 | E35: 12 | H35: 12 | I35: 7 | L35: 39 | M35: 8 | N35: 12 | Q35: 8 | R35: 12 | U35: 40
A36: 29 | B36: 1AM22CS088 | C36: KANAKA MAHWSHWARI | D36: 7 | E36: 0 | J36: 1 | K36: 4 | L36: 12 | M36: 8 | N36: 8 | Q36: 0 | R36: 0 | U36: 16
A37: 30 | B37: 1AM22CS089 | C37: KARANVEER SINGH AZAD | D37: 6 | E37: 0 | J37: 1 | K37: 1 | L37: 8 | M37: 5 | N37: 0 | Q37: 2 | R37: 4 | U37: 11
A38: 31 | B38: 1AM22CS090 | C38: KARTHIK V | E38: 8 | F38: 12 | J38: 12 | K38: 8 | L38: 40 | M38: 8 | N38: 12 | Q38: 8 | R38: 12 | U38: 40
A39: 32 | B39: 1AM22CS091 | C39: KAVYASHREE K T | D39: 7 | E39: 11 | F39: 4 | G39: 5 | H39: 8 | I39: 0 | J39: 7 | K39: 6 | L39: 30 | O39: 8 | P39: 12 | Q39: 7 | R39: 11 | S39: 6 | T39: 8 | U39: 38
A40: 33 | B40: 1AM22CS092 | C40: KEERTHANA SHENOY | F40: 8 | G40: 7 | J40: 9 | K40: 6 | L40: 30 | M40: 5 | N40: 12 | Q40: 8 | R40: 7 | U40: 32
...

Sheet 3rdB_internal
A6: SL NO. | B6: USN | C6: NAME OF THE STUDENT | D6: IA 1 | E6: IA 2 | F6: AVERAGE | G6: REDUCED__25 | H6: LAB_MARKS | I6: ASSIGNMENTS | J6: TOTAL
A8: 1 | B8: 1AM22CS059 | C8: GAGANA R M | D8: {='3rd B '!L8:L69} -> 37 | E8: {='3rd B '!U8:U69} -> 40 | F8: =AVERAGE(D8,E8) -> 38.5 | G8: =(F8/40)*25 -> 24.0625 | J8: =G8+H8+I8 -> 24.0625
A9: 2 | B9: 1AM22CS060 | C9: GANASHREE A | D9: 18 | E9: 17 | F9: =AVERAGE(D9,E9) -> 17.5 | G9: =(F9/40)*25 -> 10.9375 | J9: =G9+H9+I9 -> 10.9375
A10: 3 | B10: 1AM22CS061 | C10: GANESH B R | D10: 7 | E10: 14 | F10: =AVERAGE(D10,E10) -> 10.5 | G10: =(F10/40)*25 -> 6.5625 | J10: =G10+H10+I10 -> 6.5625
A11: 4 | B11: 1AM22CS062 | C11: GAYITHRI R | D11: 27 | E11: 23 | F11: =AVERAGE(D11,E11) -> 25 | G11: =(F11/40)*25 -> 15.625 | J11: =G11+H11+I11 -> 15.625
A12: 5 | B12: 1AM22CS063 | C12: GOLDI KUMARI | D12: 27 | E12: 32 | F12: =AVERAGE(D12,E12) -> 29.5 | G12: =(F12/40)*25 -> 18.4375 | J12: =G12+H12+I12 -> 18.4375
A13: 6 | B13: 1AM22CS064 | C13: GOPIKA M U | D13: 32 | E13: 29 | F13: =AVERAGE(D13,E13) -> 30.5 | G13: =(F13/40)*25 -> 19.0625 | J13: =G13+H13+I13 -> 19.0625
A14: 7 | B14: 1AM22CS065 | C14: GOPIMOHAN MUKHERJEE | D14: 30 | E14: 30 | F14: =AVERAGE(D14,E14) -> 30 | G14: =(F14/40)*25 -> 18.75 | J14: =G14+H14+I14 -> 18.75
A15: 8 | B15: 1AM22CS066 | C15: GOWDA NAVEENKUMAR UCHE | D15: 26 | E15: 18 | F15: =AVERAGE(D15,E15) -> 22 | G15: =(F15/40)*25 -> 13.75 | J15: =G15+H15+I15 -> 13.75
A16: 9 | B16: 1AM22CS067 | C16: GURUPRADAD | D16: 28 | E16: 13 | F16: =AVERAGE(D16,E16) -> 20.5 | G16: =(F16/40)*25 -> 12.8125 | J16: =G16+H16+I16 -> 12.8125
A17: 10 | B17: 1AM22CS068 | C17: HARASH SANGRAL | D17: 40 | E17: 33 | F17: =AVERAGE(D17,E17) -> 36.5 | G17: =(F17/40)*25 -> 22.8125 | J17: =G17+H17+I17 -> 22.8125
A18: 11 | B18: 1AM22CS069 | C18: HARI KRISHNA YADAV C | D18: 33 | E18: 39 | F18: =AVERAGE(D18,E18) -> 36 | G18: =(F18/40)*25 -> 22.5 | J18: =G18+H18+I18 -> 22.5
A19: 12 | B19: 1AM22CS070 | C19: HARSHITH G M | D19: 30 | E19: 16 | F19: =AVERAGE(D19,E19) -> 23 | G19: =(F19/40)*25 -> 14.375 | J19: =G19+H19+I19 -> 14.375
A20: 13 | B20: 1AM22CS071 | C20: HARSHITHA R | D20: 38 | E20: 39 | F20: =AVERAGE(D20,E20) -> 38.5 | G20: =(F20/40)*25 -> 24.0625 | J20: =G20+H20+I20 -> 24.0625
... A69: 64 | B69: 1AM21CS180 | C69: SHREYCHADHA | D69: 16 | E69: 8 | F69: =AVERAGE(D69,E69) -> 12 | G69: =(F69/40)*25 -> 7.5 | J69: =G69+H69+I69 -> 7.5

Sheet 3rsB_total
A6: SL NO. | B6: USN | C6: NAME OF THE STUDENT | D6: INTERNAL | E6: EXTERNAL | F6: TOTAL
A8: 1 | B8: 1AM22CS059 | C8: GAGANA R M | D8: {='3rdB_internal'!J8:J69} -> 24.0625 | F8: =D8+E8 -> 24.0625
A9: 2 | B9: 1AM22CS060 | C9: GANASHREE A | D9: 10.9375 | F9: =D9+E9 -> 10.9375
A10: 3 | B10: 1AM22CS061 | C10: GANESH B R | D10: 6.5625 | F10: =D10+E10 -> 6.5625
A11: 4 | B11: 1AM22CS062 | C11: GAYITHRI R | D11: 15.625 | F11: =D11+E11 -> 15.625
A12: 5 | B12: 1AM22CS063 | C12: GOLDI KUMARI | D12: 18.4375 | F12: =D12+E12 -> 18.4375
A13: 6 | B13: 1AM22CS064 | C13: GOPIKA M U | D13: 19.0625 | F13: =D13+E13 -> 19.0625
A14: 7 | B14: 1AM22CS065 | C14: GOPIMOHAN MUKHERJEE | D14: 18.75 | F14: =D14+E14 -> 18.75
A15: 8 | B15: 1AM22CS066 | C15: GOWDA NAVEENKUMAR UCHE | D15: 13.75 | F15: =D15+E15 -> 13.75
A16: 9 | B16: 1AM22CS067 | C16: GURUPRADAD | D16: 12.8125 | F16: =D16+E16 -> 12.8125
A17: 10 | B17: 1AM22CS068 | C17: HARASH SANGRAL | D17: 22.8125 | F17: =D17+E17 -> 22.8125
A18: 11 | B18: 1AM22CS069 | C18: HARI KRISHNA YADAV C | D18: 22.5 | F18: =D18+E18 -> 22.5
A19: 12 | B19: 1AM22CS070 | C19: HARSHITH G M | D19: 14.375 | F19: =D19+E19 -> 14.375
A20: 13 | B20: 1AM22CS071 | C20: HARSHITHA R | D20: 24.0625 | F20: =D20+E20 -> 24.0625
... A69: 64 | B69: 1AM21CS180 | C69: SHREYCHADHA | D69: 7.5 | F69: =D69+E69 -> 7.5

Sheet Sheet1
